<?xml version="1.0"?>

<robot name="sbrobot">

  <!-- Link Definitions -->
  <link name="base_footprint">
  </link>

  <link name="base_link">
    <inertial>
      <mass value="5.0"/>
      <origin xyz="0.0 0 0.55" rpy="0 0 0"/>
      <inertia ixx="0.141" ixy="0.0" ixz="0.0" iyy="0.120" iyz="0.0" izz="0.0541"/>
    </inertial>
    <collision name='collision'>
      <origin xyz="0 0 0.3" rpy="0 0 0"/>
      <geometry>
        <box size=".2 .3 .5"/>
      </geometry>
    </collision>
    <visual name='visual'>
      <origin xyz="0 0 0.3" rpy="0 0 0"/>
      <geometry>
        <box size=".2 .3 .5"/>
      </geometry>
    </visual>
  </link>

  <link name="head">
    <inertial>
      <mass value="0.1"/>
      <origin xyz="0.0 0.0 0.0" rpy="0 0 0"/>
      <inertia ixx="0.00001" ixy="0.0" ixz="0.0" iyy="0.00001" iyz="0.0" izz="0.00001"/>
    </inertial>
    <collision name='collision'>
      <origin xyz="0.0 0.0 0.0" rpy="0 0 0"/>
      <geometry>
        <box size=".1 .1 .1"/>
      </geometry>
    </collision>
    <visual name='visual'>
      <origin xyz="0 0 0" rpy="0 0 0"/>
      <geometry>
        <box size=".1 .1 .1"/>
      </geometry>
    </visual>
  </link>

  <link name="left_wheel">
    <inertial>
      <origin xyz="0 0 0" rpy="0 1.5707 1.5707"/>
      <mass value=".5"/>
      <inertia
        ixx="0.0004" ixy="0.0" ixz="0.0"
        iyy="0.0025" iyz="0.0"
        izz="0.0004"/>
    </inertial>
    <collision name="collision">
      <origin xyz="0 0 0" rpy="0 1.5707 1.5707"/>
      <geometry>
        <cylinder radius="0.1" length="0.05"/>
      </geometry>
    </collision>
    <visual name="visual">
      <origin xyz="0 0 0" rpy="0 1.5707 1.5707"/>
      <geometry>
        <cylinder radius="0.1" length="0.05"/>
      </geometry>
    </visual>
  </link>
  
  <link name="right_wheel">
     <collision name="collision">
      <origin xyz="0 0 0" rpy="0 1.5707 1.5707"/>
      <geometry>
        <cylinder radius="0.1" length="0.05"/>
      </geometry>
    </collision>
    <inertial>
      <origin xyz="0 0 0" rpy="0 1.5707 1.5707"/>
      <mass value="0.5"/>
      <inertia
        ixx="0.0004" ixy="0.0" ixz="0.0"
        iyy="0.0025" iyz="0.0"
        izz="0.0004"/>
    </inertial>
    <visual name="visual">
      <origin xyz="0 0 0" rpy="0 1.5707 1.5707"/>
      <geometry>
        <cylinder radius="0.1" length="0.05"/>
      </geometry>
    </visual>
  </link>

  <link name="imu_link">
  </link>

  <!-- Joint Definitions -->
  <joint type="fixed" name="dummy_joint">
    <origin xyz="0 0.0 0" rpy="0 0 0"/>
    <parent link="base_footprint"/>
    <child link="base_link"/>
  </joint>

  <joint type="fixed" name="head_joint">
    <origin xyz="0 0.0 0.55" rpy="0 0 0"/>
    <parent link="base_link"/>
    <child link="head"/>
  </joint>

  <joint type="continuous" name="left_wheel_hinge">
    <origin xyz="0 0.175 0.1" rpy="0 0 0"/>
    <parent link="base_link"/>
    <child link="left_wheel"/>
    <axis xyz="0 1 0"/>
    <limit effort="1.5" velocity="1000"/>
  </joint>

  <joint type="continuous" name="right_wheel_hinge">
    <origin xyz="0 -0.175 0.1" rpy="0 0 0"/>
    <parent link="base_link"/>
    <child link="right_wheel"/>
    <axis xyz="0 1 0"/>
    <limit effort="1.5" velocity="1000"/>
  </joint>

   <joint name="imu_joint" type="fixed">
    <parent link="base_link"/>
    <child link="imu_link"/>
    <origin xyz="0 0 0" rpy="0 0 0"/>
  </joint>

   <gazebo reference="base_link">
        <material>Gazebo/Red</material>
    </gazebo>

    <gazebo reference="head">
        <material>Gazebo/White</material>
    </gazebo>

    <gazebo reference="left_wheel">
        <material>Gazebo/Black</material>
    </gazebo>

    <gazebo reference="right_wheel">
        <material>Gazebo/Black</material>
    </gazebo>

    <!-- Define Gazebo plugins for robot control and sensor data integration -->
    <!-- Joint State Publisher Plugin -->
    <gazebo>
        <plugin name="gazebo_ros_joint_state_publisher"
                filename="libgazebo_ros_joint_state_publisher.so">
            <update_rate>20</update_rate>
            <!-- List all joints you want to publish state for -->
            <joint_name>left_wheel_hinge</joint_name>
            <joint_name>right_wheel_hinge</joint_name>
            <!-- Add other joints as needed -->
        </plugin>
    </gazebo>

    <!-- Differential Drive Plugin -->
    <gazebo>
        <plugin name="gazebo_ros_diff_drive"
                filename="libgazebo_ros_diff_drive.so">
            <ros>
                <namespace>/</namespace>
                <argument>--ros-args -r __ns:=/sbrobot</argument>
            </ros>
            <update_rate>10</update_rate>
            <left_joint>left_wheel_hinge</left_joint>
            <right_joint>right_wheel_hinge</right_joint>
            <wheel_separation>0.35</wheel_separation>
            <wheel_diameter>0.2</wheel_diameter>
            <command_topic>cmd_vel</command_topic>
            <odometry_topic>odom</odometry_topic>
            <odometry_frame>odom</odometry_frame>
            <robot_base_frame>base_link</robot_base_frame>
        </plugin>
    </gazebo>

    <!-- Example IMU Sensor Plugin -->
    <gazebo reference="imu_link">
    <gravity>true</gravity>
    <sensor name="imu_sensor" type="imu">
      <always_on>true</always_on>
      <update_rate>100</update_rate>
      <visualize>true</visualize>
      <topic>__default_topic__</topic>
      <plugin filename="libgazebo_ros_imu_sensor.so" name="imu_plugin">
        <topicName>imu</topicName>
        <bodyName>imu_link</bodyName>
        <updateRateHZ>10.0</updateRateHZ>
        <gaussianNoise>0.0</gaussianNoise>
        <xyzOffset>0 0 0</xyzOffset>
        <rpyOffset>0 0 0</rpyOffset>
        <frameName>imu_link</frameName>
        <initialOrientationAsReference>false</initialOrientationAsReference>
      </plugin>
      <pose>0 0 0 0 0 0</pose>
    </sensor>
  </gazebo>

  
</robot>
